Workbook

Sheet Ringkasan
A1: Rancangan Fitur Marketplace UMKM — Gap Analysis Repository myumkm
A2: Status dihitung otomatis dari sheet "Daftar Fitur" (kolom E). Ubah status di sana, ringkasan ikut berubah.
A4: Kelompok Pengguna | B4: Total Fitur | C4: ✅ Ada | D4: ❌ Belum | E4: % Selesai | F4: ⭐ Pembeda | G4: ⭐ Pembeda yang Belum Ada | H4: 🧓 Low-tech
A5: Pembeli | B5: =COUNTIF('Daftar Fitur'!$B$2:$B$101,A5) -> 37 | C5: =COUNTIFS('Daftar Fitur'!$B$2:$B$101,A5,'Daftar Fitur'!$E$2:$E$101,"Ada") -> 22 | D5: =COUNTIFS('Daftar Fitur'!$B$2:$B$101,A5,'Daftar Fitur'!$E$2:$E$101,"Belum") -> 15 | E5: =IF(B5=0,0,C5/B5) -> 0.59459459 | F5: =COUNTIFS('Daftar Fitur'!$B$2:$B$101,A5,'Daftar Fitur'!$F$2:$F$101,"Ya") -> 5 | G5: =COUNTIFS('Daftar Fitur'!$B$2:$B$101,A5,'Daftar Fitur'!$F$2:$F$101,"Ya",'Daftar Fitur'!$E$2:$E$101,"Belum") -> 4 | H5: =COUNTIFS('Daftar Fitur'!$B$2:$B$101,A5,'Daftar Fitur'!$G$2:$G$101,"Ya") -> 9
A6: Penjual / Pelaku UMKM | B6: =COUNTIF('Daftar Fitur'!$B$2:$B$101,A6) -> 41 | C6: =COUNTIFS('Daftar Fitur'!$B$2:$B$101,A6,'Daftar Fitur'!$E$2:$E$101,"Ada") -> 21 | D6: =COUNTIFS('Daftar Fitur'!$B$2:$B$101,A6,'Daftar Fitur'!$E$2:$E$101,"Belum") -> 20 | E6: =IF(B6=0,0,C6/B6) -> 0.51219512 | F6: =COUNTIFS('Daftar Fitur'!$B$2:$B$101,A6,'Daftar Fitur'!$F$2:$F$101,"Ya") -> 10 | G6: =COUNTIFS('Daftar Fitur'!$B$2:$B$101,A6,'Daftar Fitur'!$F$2:$F$101,"Ya",'Daftar Fitur'!$E$2:$E$101,"Belum") -> 8 | H6: =COUNTIFS('Daftar Fitur'!$B$2:$B$101,A6,'Daftar Fitur'!$G$2:$G$101,"Ya") -> 8
A7: Admin / Pengelola Platform | B7: =COUNTIF('Daftar Fitur'!$B$2:$B$101,A7) -> 22 | C7: =COUNTIFS('Daftar Fitur'!$B$2:$B$101,A7,'Daftar Fitur'!$E$2:$E$101,"Ada") -> 9 | D7: =COUNTIFS('Daftar Fitur'!$B$2:$B$101,A7,'Daftar Fitur'!$E$2:$E$101,"Belum") -> 13 | E7: =IF(B7=0,0,C7/B7) -> 0.40909091 | F7: =COUNTIFS('Daftar Fitur'!$B$2:$B$101,A7,'Daftar Fitur'!$F$2:$F$101,"Ya") -> 2 | G7: =COUNTIFS('Daftar Fitur'!$B$2:$B$101,A7,'Daftar Fitur'!$F$2:$F$101,"Ya",'Daftar Fitur'!$E$2:$E$101,"Belum") -> 2 | H7: =COUNTIFS('Daftar Fitur'!$B$2:$B$101,A7,'Daftar Fitur'!$G$2:$G$101,"Ya") -> 0
A8: TOTAL | B8: =SUM(B5:B7) -> 100 | C8: =SUM(C5:C7) -> 52 | D8: =SUM(D5:D7) -> 48 | E8: =IF(B8=0,0,C8/B8) -> 0.52 | F8: =SUM(F5:F7) -> 17 | G8: =SUM(G5:G7) -> 14 | H8: =SUM(H5:H7) -> 17
A10: Keterangan
A11: Ada | B11: Fitur inti sudah ada di kode repo (catatan menjelaskan batasan bila sebagian).
A12: Belum | B12: Fitur belum ada di repo.
A13: ⭐ Pembeda | B13: Fitur yang membedakan dari marketplace besar.
A14: 🧓 Low-tech | B14: Dirancang ramah UMKM/pengguna gagap teknologi.
A15: Kolom Prioritas | B15: Sel kuning di "Daftar Fitur" kolom K: diisi tim (dropdown P1–P4).
A16: Sumber | B16: Analisis kode repo xaralien/myumkm (CodeIgniter 3), per 13 Okt 2026. Dibaca dari kode, aplikasi tidak dijalankan.

Sheet Daftar Fitur
A1: No | B1: Kelompok Pengguna | C1: Sub-kategori | D1: Fitur | E1: Status di Repo | F1: Pembeda (⭐) | G1: Low-tech Friendly (🧓) | H1: Pain Point | I1: Fungsi Utama | J1: Bukti di Repo / Catatan | K1: Prioritas
A2: 1 | B2: Pembeli | C2: Akun & Akses | D2: Daftar & masuk akun | E2: Ada | H2: Pembeli perlu riwayat pesanan tersimpan | I2: Registrasi dengan nama, email, nomor WhatsApp. | J2: Auth.php
A3: 2 | B3: Pembeli | C3: Akun & Akses | D3: Belanja tanpa akun (guest checkout) | E3: Ada | G3: Ya | H3: Pembeli lokal malas daftar hanya untuk sekali beli | I3: Checkout cukup nama + nomor WA; pesanan dibuka lewat token. | J3: orders.user_id boleh NULL, Checkout::done/{token}
A4: 3 | B4: Pembeli | C4: Akun & Akses | D4: Lacak pesanan dengan nomor pesanan + nomor WA | E4: Ada | G4: Ya | H4: Pembeli tamu tidak punya akun untuk mengecek status | I4: Form lacak sederhana tanpa login. | J4: Track.php
A5: 4 | B5: Pembeli | C5: Akun & Akses | D5: Login OTP WhatsApp / tanpa kata sandi | E5: Belum | G5: Ya | H5: Pembeli sering lupa sandi | I5: Masuk cukup dengan kode OTP dikirim ke WA.
A6: 5 | B6: Pembeli | C6: Akun & Akses | D6: Lupa kata sandi mandiri | E6: Belum | H6: Saat ini reset sandi harus lewat admin | I6: Tautan/OTP reset sandi sendiri. | J6: Repo hanya punya reset oleh admin: admin/Users::sandi
A7: 6 | B7: Pembeli | C7: Akun & Akses | D7: Profil & ubah sandi | E7: Ada | H7: Data kontak berubah | I7: Ubah nama, foto, nomor, sandi. | J7: Akun::profil
A8: 7 | B8: Pembeli | C8: Penemuan Produk | D8: Katalog berbasis lokasi ("dekat saya") | E8: Ada | F8: Ya | H8: Pembeli ingin produk UMKM tetangga, ongkir murah & cepat | I8: Pilih kecamatan atau titik GPS, urutan produk mendahulukan toko terdekat. | J8: Location.php, Product_model::proximity_sql, toko_sekitar
A9: 8 | B9: Pembeli | C9: Penemuan Produk | D9: Pencarian & filter | E9: Ada | H9: Sulit menemukan produk spesifik | I9: Cari kata kunci, filter kategori & rentang harga. | J9: Shop.php, Product_model::build_filter, price_range
A10: 9 | B10: Pembeli | C10: Penemuan Produk | D10: Urutkan hasil | E10: Ada | H10: Ingin yang termurah/terbaik dulu | I10: Terbaru, ulasan terbaik, harga, nama. | J10: Product_model::sort_options
A11: 10 | B11: Pembeli | C11: Penemuan Produk | D11: Kategori UMKM dengan ikon | E11: Ada | H11: Pengguna awam lebih cepat mengenali gambar daripada teks | I11: Kartu kategori berikon di beranda. | J11: 15_kategori_umkm.sql
A12: 11 | B12: Pembeli | C12: Penemuan Produk | D12: Halaman toko | E12: Ada | H12: Pembeli ingin melihat reputasi & produk lain penjual | I12: Profil toko, nilai rata-rata, daftar produk. | J12: Toko.php, parts/toko_nilai.php
A13: 12 | B13: Pembeli | C13: Penemuan Produk | D13: Detail produk dengan varian & add-on | E13: Ada | H13: Produk UMKM sering punya ukuran/rasa/tambahan | I13: Pilih varian (dengan foto & selisih harga) dan add-on. | J13: Product_model::variants, addons_for_product
A14: 13 | B14: Pembeli | C14: Penemuan Produk | D14: Wishlist / simpan produk favorit | E14: Belum | H14: Pembeli ingin membeli nanti | I14: Tombol ♥ dan daftar favorit.
A15: 14 | B15: Pembeli | C15: Penemuan Produk | D15: Ikuti toko | E15: Belum | H15: Pelanggan setia tidak tahu kalau toko langganannya punya produk baru | I15: Follow toko + kabar produk baru.
A16: 15 | B16: Pembeli | C16: Penemuan Produk | D16: Rekomendasi & "terlaris" | E16: Belum | H16: Pembeli bingung memilih | I16: Rekomendasi berdasarkan riwayat, label terlaris di sekitar.
A17: 16 | B17: Pembeli | C17: Penemuan Produk | D17: Label "Produk Lokal / Halal / P-IRT / Buatan Tangan" | E17: Belum | F17: Ya | H17: Pembeli ingin yakin akan keamanan & keaslian produk UMKM | I17: Lencana terverifikasi di kartu produk.
A18: 17 | B18: Pembeli | C18: Penemuan Produk | D18: Bagikan produk ke WhatsApp | E18: Belum | G18: Ya | H18: Promosi UMKM paling efektif lewat grup WA | I18: Tombol share dengan pesan siap kirim. | J18: Ada kode tombol WA di v_produk.php tapi dikomentari
A19: 18 | B19: Pembeli | C19: Keranjang, Checkout & Pembayaran | D19: Keranjang & "Beli Langsung" | E19: Ada | H19: Ingin beli cepat satu barang | I19: Keranjang per toko dan jalur beli langsung. | J19: Cart.php, Cart_lib::mode_langsung
A20: 19 | B20: Pembeli | C20: Keranjang, Checkout & Pembayaran | D20: Buku alamat | E20: Ada | H20: Mengetik alamat berulang; penerima sering bukan pembeli | I20: Simpan banyak alamat ("Rumah", "Rumah Ibu"), pilih saat checkout. | J20: 22_buku_alamat.sql, Akun::alamat
A21: 20 | B21: Pembeli | C21: Keranjang, Checkout & Pembayaran | D21: Ongkir otomatis berdasarkan wilayah | E21: Ada | H21: Ongkir tidak jelas sebelum bayar | I21: Tarif kecamatan/kota/provinsi/luar provinsi dari toko, plus gratis ongkir minimal belanja. | J21: Cart_lib::shipping_fee
A22: 21 | B22: Pembeli | C22: Keranjang, Checkout & Pembayaran | D22: Pembayaran online (VA/QRIS/e-wallet via Duitku) | E22: Ada | H22: Transfer manual rawan salah & lama dicek | I22: Pembayaran terverifikasi otomatis via callback. | J22: Payment.php, libraries/Duitku.php
A23: 22 | B23: Pembeli | C23: Keranjang, Checkout & Pembayaran | D23: COD / bayar di tempat | E23: Belum | G23: Ya | H23: Banyak pembeli daerah belum percaya bayar di muka | I23: Opsi COD dengan batas nominal per toko. | J23: Ada sisa logika cod di Payment.php, tetapi Checkout::place selalu memakai Duitku
A24: 23 | B24: Pembeli | C24: Keranjang, Checkout & Pembayaran | D24: Voucher & promo | E24: Belum | H24: Pembeli mencari potongan harga | I24: Kode voucher toko/platform.
A25: 24 | B25: Pembeli | C25: Keranjang, Checkout & Pembayaran | D25: Checkout multi-toko | E25: Belum | F25: Ya | H25: Keranjang saat ini hanya untuk satu toko | I25: Beli dari beberapa toko dalam satu pembayaran.
A26: 25 | B26: Pembeli | C26: Keranjang, Checkout & Pembayaran | D26: Pre-order fleksibel (DP, tanggal ambil, kuota) | E26: Belum | F26: Ya | H26: Kue, katering, kerajinan dibuat berdasarkan pesanan | I26: Pilih tanggal kirim/ambil, bayar DP, kuota harian. | J26: Repo baru punya waktu_proses_hari di level toko
A27: 26 | B27: Pembeli | C27: Keranjang, Checkout & Pembayaran | D27: Ambil sendiri di toko (pickup) | E27: Belum | F27: Ya | H27: Tetangga satu kecamatan lebih suka mengambil sendiri | I27: Opsi ongkir 0 + jam ambil.
A28: 27 | B28: Pembeli | C28: Pasca-Pembelian | D28: Riwayat & status pesanan | E28: Ada | H28: Pembeli cemas menunggu | I28: Daftar pesanan dengan linimasa status & nomor resi. | J28: Akun::pesanan, Order_model::logs
A29: 28 | B29: Pembeli | C29: Pasca-Pembelian | D29: Batalkan pesanan dengan alasan | E29: Ada | H29: Salah pesan | I29: Pembatalan oleh pembeli, stok dikembalikan. | J29: Checkout::batal, Stok_lib::kembalikan
A30: 29 | B30: Pembeli | C30: Pasca-Pembelian | D30: Konfirmasi pesanan diterima | E30: Ada | H30: Dana penjual tertahan tanpa kepastian | I30: Tombol "Pesanan diterima". | J30: Checkout::terima
A31: 30 | B31: Pembeli | C31: Pasca-Pembelian | D31: Ajukan pengembalian dana (refund) | E31: Ada | H31: Barang tidak sesuai | I31: Form refund yang ditinjau penjual lalu diproses admin. | J31: Checkout::refund, Refund_model
A32: 31 | B32: Pembeli | C32: Pasca-Pembelian | D32: Ulasan dengan foto/video | E32: Ada | H32: Pembeli lain butuh bukti nyata | I32: Rating bintang + media, hanya dari pembeli asli, filter ulasan. | J32: Ulasan.php, 19_ulasan.sql
A33: 32 | B33: Pembeli | C33: Pasca-Pembelian | D33: Chat dengan toko (sebelum & sesudah beli) + lampiran | E33: Ada | H33: Ingin bertanya sebelum membeli tanpa pindah ke WA | I33: "Tanya ke toko" dan percakapan per pesanan. | J33: Chat.php, 18_tanya_toko.sql
A34: 33 | B34: Pembeli | C34: Pasca-Pembelian | D34: Notifikasi di dalam situs | E34: Ada | H34: Tidak tahu ada balasan/perubahan status | I34: Lonceng notifikasi & inbox. | J34: Akun::notif, inbox_json
A35: 34 | B35: Pembeli | C35: Pasca-Pembelian | D35: Notifikasi WhatsApp / email otomatis | E35: Belum | G35: Ya | H35: Pengguna jarang membuka web, tapi selalu membuka WA | I35: Kabar status pesanan dikirim ke WA.
A36: 35 | B36: Pembeli | C36: Pengalaman & Aksesibilitas | D36: Tampilan khusus HP otomatis | E36: Ada | G36: Ya | H36: Mayoritas pengguna UMKM memakai HP murah | I36: Deteksi perangkat & tampilan mobile terpisah, bisa ditukar manual. | J36: Tampilan_lib, views/mobile/
A37: 36 | B37: Pembeli | C37: Pengalaman & Aksesibilitas | D37: PWA / mode hemat kuota | E37: Belum | G37: Ya | H37: Sinyal lemah di daerah | I37: Bisa dipasang di layar utama, gambar ringan, cache offline.
A38: 37 | B38: Pembeli | C38: Pengalaman & Aksesibilitas | D38: Mode huruf besar & bahasa daerah | E38: Belum | G38: Ya | H38: Pengguna lansia/kurang terbiasa bahasa formal | I38: Pengaturan ukuran huruf, pilihan bahasa.
A39: 38 | B39: Penjual / Pelaku UMKM | C39: Onboarding & Profil Toko | D39: Buka toko langsung dari akun pembeli | E39: Ada | G39: Ya | H39: Pendaftaran penjual di marketplace besar panjang & membingungkan | I39: Satu akun = satu toko, form singkat. | J39: Akun::buka_toko
A40: 39 | B40: Penjual / Pelaku UMKM | C40: Onboarding & Profil Toko | D40: Profil toko dengan titik peta | E40: Ada | H40: Pembeli & kurir sulit menemukan lokasi | I40: Alamat, kecamatan, titik koordinat via peta (Leaflet/OSM). | J40: Seller::update_profile, valid_koordinat
...

Sheet Roadmap
A1: Tahap | B1: Fitur yang Direkomendasikan
A2: Quick win (1–2 sprint) | B2: notifikasi WhatsApp (pembeli & penjual), lupa sandi mandiri, tombol share WA (kodenya sudah ada, tinggal diaktifkan), peringatan stok menipis, mode libur toko, template balasan chat.
A3: Pembeda utama (2–4 sprint) | B3: pembukuan sederhana + laporan penjualan, pre-order fleksibel per produk (DP & kalender), COD dengan batas nominal, pickup di toko.
A4: Naik kelas (jangka menengah) | B4: Akademi UMKM, skor "Naik Kelas", bantuan legalitas + lencana verifikasi, laporan siap KUR, manajemen pendamping.
A5: Skala (jangka panjang) | B5: integrasi agregator ekspedisi, checkout multi-toko, voucher platform, POS offline, PWA.
